[31m[1mERROR   [0m test_flow_product:test_flow_product.py:606 Unexpected error during login: ('Connection aborted.', ConnectionResetError(10054, 'An existing connection was forcibly closed by the remote host', None, 10054, None))
[33mWARNING [0m urllib3.connectionpool:connectionpool.py:868 Retrying (Retry(total=2, connect=None, read=None, redirect=None, status=None)) after connection broken by 'NewConnectionError('<urllib3.connection.HTTPConnection object at 0x0000029EFA3F5CD0>: Failed to establish a new connection: [WinError 10061] No connection could be made because the target machine actively refused it')': /session/bb13603a03ebf183500afe3e7a8ecfe4/screenshot
[33mWARNING [0m urllib3.connectionpool:connectionpool.py:868 Retrying (Retry(total=1, connect=None, read=None, redirect=None, status=None)) after connection broken by 'NewConnectionError('<urllib3.connection.HTTPConnection object at 0x0000029EFA3F6060>: Failed to establish a new connection: [WinError 10061] No connection could be made because the target machine actively refused it')': /session/bb13603a03ebf183500afe3e7a8ecfe4/screenshot
[33mWARNING [0m urllib3.connectionpool:connectionpool.py:868 Retrying (Retry(total=0, connect=None, read=None, redirect=None, status=None)) after connection broken by 'NewConnectionError('<urllib3.connection.HTTPConnection object at 0x0000029EFA3A1130>: Failed to establish a new connection: [WinError 10061] No connection could be made because the target machine actively refused it')': /session/bb13603a03ebf183500afe3e7a8ecfe4/screenshot
[33mWARNING [0m urllib3.connectionpool:connectionpool.py:868 Retrying (Retry(total=2, connect=None, read=None, redirect=None, status=None)) after connection broken by 'NewConnectionError('<urllib3.connection.HTTPConnection object at 0x0000029EFA34DAE0>: Failed to establish a new connection: [WinError 10061] No connection could be made because the target machine actively refused it')': /session/bb13603a03ebf183500afe3e7a8ecfe4
[33mWARNING [0m urllib3.connectionpool:connectionpool.py:868 Retrying (Retry(total=1, connect=None, read=None, redirect=None, status=None)) after connection broken by 'NewConnectionError('<urllib3.connection.HTTPConnection object at 0x0000029EFA34EF10>: Failed to establish a new connection: [WinError 10061] No connection could be made because the target machine actively refused it')': /session/bb13603a03ebf183500afe3e7a8ecfe4
[33mWARNING [0m urllib3.connectionpool:connectionpool.py:868 Retrying (Retry(total=0, connect=None, read=None, redirect=None, status=None)) after connection broken by 'NewConnectionError('<urllib3.connection.HTTPConnection object at 0x0000029EFA44D260>: Failed to establish a new connection: [WinError 10061] No connection could be made because the target machine actively refused it')': /session/bb13603a03ebf183500afe3e7a8ecfe4